[2024-09-14T16:26:28.344+0000] {taskinstance.py:1087} INFO - Dependencies all met for <TaskInstance: my_first_dag.transform manual__2024-09-14T16:26:26.101365+00:00 [queued]>
[2024-09-14T16:26:28.348+0000] {taskinstance.py:1087} INFO - Dependencies all met for <TaskInstance: my_first_dag.transform manual__2024-09-14T16:26:26.101365+00:00 [queued]>
[2024-09-14T16:26:28.348+0000] {taskinstance.py:1283} INFO - 
--------------------------------------------------------------------------------
[2024-09-14T16:26:28.348+0000] {taskinstance.py:1284} INFO - Starting attempt 1 of 1
[2024-09-14T16:26:28.348+0000] {taskinstance.py:1285} INFO - 
--------------------------------------------------------------------------------
[2024-09-14T16:26:28.355+0000] {taskinstance.py:1304} INFO - Executing <Task(_PythonDecoratedOperator): transform> on 2024-09-14 16:26:26.101365+00:00
[2024-09-14T16:26:28.357+0000] {standard_task_runner.py:55} INFO - Started process 2495 to run task
[2024-09-14T16:26:28.359+0000] {standard_task_runner.py:82} INFO - Running: ['***', 'tasks', 'run', 'my_first_dag', 'transform', 'manual__2024-09-14T16:26:26.101365+00:00', '--job-id', '21', '--raw', '--subdir', 'DAGS_FOLDER/first_dag.py', '--cfg-path', '/tmp/tmp76rd5t1e']
[2024-09-14T16:26:28.359+0000] {standard_task_runner.py:83} INFO - Job 21: Subtask transform
[2024-09-14T16:26:28.388+0000] {task_command.py:389} INFO - Running <TaskInstance: my_first_dag.transform manual__2024-09-14T16:26:26.101365+00:00 [running]> on host 769272fb41c3
[2024-09-14T16:26:28.424+0000] {taskinstance.py:1513} INFO - Exporting the following env vars:
AIRFLOW_CTX_DAG_OWNER=***
AIRFLOW_CTX_DAG_ID=my_first_dag
AIRFLOW_CTX_TASK_ID=transform
AIRFLOW_CTX_EXECUTION_DATE=2024-09-14T16:26:26.101365+00:00
AIRFLOW_CTX_TRY_NUMBER=1
AIRFLOW_CTX_DAG_RUN_ID=manual__2024-09-14T16:26:26.101365+00:00
[2024-09-14T16:26:28.425+0000] {taskinstance.py:1772} ERROR - Task failed with exception
Traceback (most recent call last):
  File "/home/airflow/.local/lib/python3.7/site-packages/airflow/decorators/base.py", line 217, in execute
    return_value = super().execute(context)
  File "/home/airflow/.local/lib/python3.7/site-packages/airflow/operators/python.py", line 175, in execute
    return_value = self.execute_callable()
  File "/home/airflow/.local/lib/python3.7/site-packages/airflow/operators/python.py", line 192, in execute_callable
    return self.python_callable(*self.op_args, **self.op_kwargs)
  File "/opt/airflow/dags/first_dag.py", line 68, in transform
    for item in order_data_dict.items():
AttributeError: 'list' object has no attribute 'items'
[2024-09-14T16:26:28.429+0000] {taskinstance.py:1327} INFO - Marking task as FAILED. dag_id=my_first_dag, task_id=transform, execution_date=20240914T162626, start_date=20240914T162628, end_date=20240914T162628
[2024-09-14T16:26:28.434+0000] {standard_task_runner.py:105} ERROR - Failed to execute job 21 for task transform ('list' object has no attribute 'items'; 2495)
[2024-09-14T16:26:28.459+0000] {local_task_job.py:159} INFO - Task exited with return code 1
[2024-09-14T16:26:28.476+0000] {taskinstance.py:2582} INFO - 0 downstream tasks scheduled from follow-on schedule check
