[2024-09-15T06:50:50.244+0000] {taskinstance.py:1087} INFO - Dependencies all met for <TaskInstance: save_city_info_weather_v01.insert_data manual__2024-09-15T06:50:46.140172+00:00 [queued]>
[2024-09-15T06:50:50.249+0000] {taskinstance.py:1087} INFO - Dependencies all met for <TaskInstance: save_city_info_weather_v01.insert_data manual__2024-09-15T06:50:46.140172+00:00 [queued]>
[2024-09-15T06:50:50.249+0000] {taskinstance.py:1283} INFO - 
--------------------------------------------------------------------------------
[2024-09-15T06:50:50.249+0000] {taskinstance.py:1284} INFO - Starting attempt 1 of 6
[2024-09-15T06:50:50.249+0000] {taskinstance.py:1285} INFO - 
--------------------------------------------------------------------------------
[2024-09-15T06:50:50.256+0000] {taskinstance.py:1304} INFO - Executing <Task(PostgresOperator): insert_data> on 2024-09-15 06:50:46.140172+00:00
[2024-09-15T06:50:50.259+0000] {standard_task_runner.py:55} INFO - Started process 427 to run task
[2024-09-15T06:50:50.262+0000] {standard_task_runner.py:82} INFO - Running: ['***', 'tasks', 'run', 'save_city_info_weather_v01', 'insert_data', 'manual__2024-09-15T06:50:46.140172+00:00', '--job-id', '311', '--raw', '--subdir', 'DAGS_FOLDER/saver_info.py', '--cfg-path', '/tmp/tmpix9yp3k9']
[2024-09-15T06:50:50.262+0000] {standard_task_runner.py:83} INFO - Job 311: Subtask insert_data
[2024-09-15T06:50:50.298+0000] {task_command.py:389} INFO - Running <TaskInstance: save_city_info_weather_v01.insert_data manual__2024-09-15T06:50:46.140172+00:00 [running]> on host 0c5fe11d0c9c
[2024-09-15T06:50:50.336+0000] {taskinstance.py:1513} INFO - Exporting the following env vars:
AIRFLOW_CTX_DAG_OWNER=me
AIRFLOW_CTX_DAG_ID=save_city_info_weather_v01
AIRFLOW_CTX_TASK_ID=insert_data
AIRFLOW_CTX_EXECUTION_DATE=2024-09-15T06:50:46.140172+00:00
AIRFLOW_CTX_TRY_NUMBER=1
AIRFLOW_CTX_DAG_RUN_ID=manual__2024-09-15T06:50:46.140172+00:00
[2024-09-15T06:50:50.337+0000] {sql.py:253} INFO - Executing: insert into weathers (city_name, max_temp, min_temp, wind, descript)
        values (%(sname)s, %(max_temp)s, %(min_temp)s, %(wind)s, %(descript)s);
[2024-09-15T06:50:50.341+0000] {base.py:73} INFO - Using connection ID 'postgres_localhost' for task execution.
[2024-09-15T06:50:50.471+0000] {base.py:73} INFO - Using connection ID 'postgres_localhost' for task execution.
[2024-09-15T06:50:50.479+0000] {sql.py:364} INFO - Running statement: insert into weathers (city_name, max_temp, min_temp, wind, descript)
        values (%(sname)s, %(max_temp)s, %(min_temp)s, %(wind)s, %(descript)s);, parameters: {'sname': '{{ti.xcom_pull(task_ids="fetcher_data", key="name")}}', 'max_temp': '{{ti.xcom_pull(task_ids="fetcher_data", key="max_temp")}}', 'min_temp': '{{ti.xcom_pull(task_ids="fetcher_data", key="min_temp")}}', 'wind': '{{ti.xcom_pull(task_ids="fetcher_data", key="wind_speed")}}', 'descript': '{{ti.xcom_pull(task_ids="fetcher_data", key="description")}}'}
[2024-09-15T06:50:50.483+0000] {taskinstance.py:1772} ERROR - Task failed with exception
Traceback (most recent call last):
  File "/home/airflow/.local/lib/python3.7/site-packages/airflow/providers/common/sql/operators/sql.py", line 261, in execute
    return_last=self.return_last,
  File "/home/airflow/.local/lib/python3.7/site-packages/airflow/providers/common/sql/hooks/sql.py", line 338, in run
    self._run_command(cur, sql_statement, parameters)
  File "/home/airflow/.local/lib/python3.7/site-packages/airflow/providers/common/sql/hooks/sql.py", line 367, in _run_command
    cur.execute(sql_statement, parameters)
psycopg2.errors.UndefinedColumn: column "descript" of relation "weathers" does not exist
LINE 1: ...nto weathers (city_name, max_temp, min_temp, wind, descript)
                                                              ^

[2024-09-15T06:50:50.491+0000] {taskinstance.py:1327} INFO - Marking task as UP_FOR_RETRY. dag_id=save_city_info_weather_v01, task_id=insert_data, execution_date=20240915T065046, start_date=20240915T065050, end_date=20240915T065050
[2024-09-15T06:50:50.499+0000] {standard_task_runner.py:105} ERROR - Failed to execute job 311 for task insert_data (column "descript" of relation "weathers" does not exist
LINE 1: ...nto weathers (city_name, max_temp, min_temp, wind, descript)
                                                              ^
; 427)
[2024-09-15T06:50:50.525+0000] {local_task_job.py:159} INFO - Task exited with return code 1
[2024-09-15T06:50:50.538+0000] {taskinstance.py:2582} INFO - 0 downstream tasks scheduled from follow-on schedule check
