[2024-09-15T06:49:55.625+0000] {taskinstance.py:1087} INFO - Dependencies all met for <TaskInstance: save_city_info_weather_v01.insert_data manual__2024-09-14T21:00:41.801690+00:00 [queued]>
[2024-09-15T06:49:55.637+0000] {taskinstance.py:1087} INFO - Dependencies all met for <TaskInstance: save_city_info_weather_v01.insert_data manual__2024-09-14T21:00:41.801690+00:00 [queued]>
[2024-09-15T06:49:55.646+0000] {taskinstance.py:1283} INFO - 
--------------------------------------------------------------------------------
[2024-09-15T06:49:55.657+0000] {taskinstance.py:1284} INFO - Starting attempt 6 of 6
[2024-09-15T06:49:55.663+0000] {taskinstance.py:1285} INFO - 
--------------------------------------------------------------------------------
[2024-09-15T06:49:55.774+0000] {taskinstance.py:1304} INFO - Executing <Task(PostgresOperator): insert_data> on 2024-09-14 21:00:41.801690+00:00
[2024-09-15T06:49:55.825+0000] {standard_task_runner.py:55} INFO - Started process 336 to run task
[2024-09-15T06:49:55.854+0000] {standard_task_runner.py:82} INFO - Running: ['***', 'tasks', 'run', 'save_city_info_weather_v01', 'insert_data', 'manual__2024-09-14T21:00:41.801690+00:00', '--job-id', '305', '--raw', '--subdir', 'DAGS_FOLDER/saver_info.py', '--cfg-path', '/tmp/tmpps7go8o2']
[2024-09-15T06:49:55.856+0000] {standard_task_runner.py:83} INFO - Job 305: Subtask insert_data
[2024-09-15T06:49:55.993+0000] {task_command.py:389} INFO - Running <TaskInstance: save_city_info_weather_v01.insert_data manual__2024-09-14T21:00:41.801690+00:00 [running]> on host 0c5fe11d0c9c
[2024-09-15T06:49:56.018+0000] {abstractoperator.py:596} ERROR - Exception rendering Jinja template for task 'insert_data', field 'sql'. Template: 'sql/ins.sql'
Traceback (most recent call last):
  File "/home/airflow/.local/lib/python3.7/site-packages/airflow/models/abstractoperator.py", line 589, in _do_render_template_fields
    seen_oids,
  File "/home/airflow/.local/lib/python3.7/site-packages/airflow/models/abstractoperator.py", line 640, in render_template
    template = jinja_env.get_template(value)
  File "/home/airflow/.local/lib/python3.7/site-packages/jinja2/environment.py", line 1010, in get_template
    return self._load_template(name, globals)
  File "/home/airflow/.local/lib/python3.7/site-packages/jinja2/environment.py", line 969, in _load_template
    template = self.loader.load(self, name, self.make_globals(globals))
  File "/home/airflow/.local/lib/python3.7/site-packages/jinja2/loaders.py", line 126, in load
    source, filename, uptodate = self.get_source(environment, name)
  File "/home/airflow/.local/lib/python3.7/site-packages/jinja2/loaders.py", line 218, in get_source
    raise TemplateNotFound(template)
jinja2.exceptions.TemplateNotFound: sql/ins.sql
[2024-09-15T06:49:56.019+0000] {taskinstance.py:1772} ERROR - Task failed with exception
Traceback (most recent call last):
  File "/home/airflow/.local/lib/python3.7/site-packages/airflow/models/taskinstance.py", line 1378, in _run_raw_task
    self._execute_task_with_callbacks(context, test_mode)
  File "/home/airflow/.local/lib/python3.7/site-packages/airflow/models/taskinstance.py", line 1497, in _execute_task_with_callbacks
    task_orig = self.render_templates(context=context)
  File "/home/airflow/.local/lib/python3.7/site-packages/airflow/models/taskinstance.py", line 2119, in render_templates
    original_task.render_template_fields(context)
  File "/home/airflow/.local/lib/python3.7/site-packages/airflow/models/baseoperator.py", line 1196, in render_template_fields
    self._do_render_template_fields(self, self.template_fields, context, jinja_env, set())
  File "/home/airflow/.local/lib/python3.7/site-packages/airflow/utils/session.py", line 75, in wrapper
    return func(*args, session=session, **kwargs)
  File "/home/airflow/.local/lib/python3.7/site-packages/airflow/models/abstractoperator.py", line 589, in _do_render_template_fields
    seen_oids,
  File "/home/airflow/.local/lib/python3.7/site-packages/airflow/models/abstractoperator.py", line 640, in render_template
    template = jinja_env.get_template(value)
  File "/home/airflow/.local/lib/python3.7/site-packages/jinja2/environment.py", line 1010, in get_template
    return self._load_template(name, globals)
  File "/home/airflow/.local/lib/python3.7/site-packages/jinja2/environment.py", line 969, in _load_template
    template = self.loader.load(self, name, self.make_globals(globals))
  File "/home/airflow/.local/lib/python3.7/site-packages/jinja2/loaders.py", line 126, in load
    source, filename, uptodate = self.get_source(environment, name)
  File "/home/airflow/.local/lib/python3.7/site-packages/jinja2/loaders.py", line 218, in get_source
    raise TemplateNotFound(template)
jinja2.exceptions.TemplateNotFound: sql/ins.sql
[2024-09-15T06:49:56.033+0000] {taskinstance.py:1327} INFO - Marking task as FAILED. dag_id=save_city_info_weather_v01, task_id=insert_data, execution_date=20240914T210041, start_date=20240915T064955, end_date=20240915T064956
[2024-09-15T06:49:56.045+0000] {standard_task_runner.py:105} ERROR - Failed to execute job 305 for task insert_data (sql/ins.sql; 336)
[2024-09-15T06:49:56.084+0000] {local_task_job.py:159} INFO - Task exited with return code 1
[2024-09-15T06:49:56.098+0000] {taskinstance.py:2582} INFO - 0 downstream tasks scheduled from follow-on schedule check
